2021-04-09 15:01:57,877 INFO    MainThread:6392 [internal.py:wandb_internal():91] W&B internal server running at pid: 6392, started at: 2021-04-09 15:01:57.871587
2021-04-09 15:01:57,885 DEBUG   SenderThread:6392 [sender.py:send():160] send: header
2021-04-09 15:01:57,886 INFO    WriterThread:6392 [datastore.py:open_for_write():77] open: C:\Users\Leo Huang\Desktop\GP-Derivatives-Variational-Inference\experiments\wandb\run-20210409_150156-w5vz35oh\run-w5vz35oh.wandb
2021-04-09 15:01:57,886 DEBUG   HandlerThread:6392 [handler.py:handle_request():120] handle_request: check_version
2021-04-09 15:01:57,886 DEBUG   SenderThread:6392 [sender.py:send():160] send: request
2021-04-09 15:01:57,890 DEBUG   SenderThread:6392 [sender.py:send_request():169] send_request: check_version
2021-04-09 15:01:58,042 DEBUG   SenderThread:6392 [sender.py:send():160] send: run
2021-04-09 15:01:58,252 ERROR   SenderThread:6392 [internal_api.py:execute():126] 404 response executing GraphQL.
2021-04-09 15:01:58,273 ERROR   SenderThread:6392 [internal_api.py:execute():127] {"errors":[{"message":"project not found","path":["upsertBucket"]}],"data":{"upsertBucket":null}}
2021-04-09 15:01:59,046 INFO    WriterThread:6392 [datastore.py:close():258] close: C:\Users\Leo Huang\Desktop\GP-Derivatives-Variational-Inference\experiments\wandb\run-20210409_150156-w5vz35oh\run-w5vz35oh.wandb
2021-04-09 15:01:59,046 INFO    HandlerThread:6392 [handler.py:finish():624] shutting down handler
2021-04-09 15:01:59,046 ERROR   MainThread:6392 [internal.py:wandb_internal():158] Thread SenderThread:
Traceback (most recent call last):
  File "C:\Users\Leo Huang\AppData\Local\Programs\Python\Python37\lib\site-packages\wandb\old\retry.py", line 96, in __call__
    result = self._call_fn(*args, **kwargs)
  File "C:\Users\Leo Huang\AppData\Local\Programs\Python\Python37\lib\site-packages\wandb\sdk\internal\internal_api.py", line 129, in execute
    six.reraise(*sys.exc_info())
  File "C:\Users\Leo Huang\AppData\Local\Programs\Python\Python37\lib\site-packages\six.py", line 703, in reraise
    raise value
  File "C:\Users\Leo Huang\AppData\Local\Programs\Python\Python37\lib\site-packages\wandb\sdk\internal\internal_api.py", line 123, in execute
    return self.client.execute(*args, **kwargs)
  File "C:\Users\Leo Huang\AppData\Local\Programs\Python\Python37\lib\site-packages\wandb\vendor\gql-0.2.0\gql\client.py", line 52, in execute
    result = self._get_result(document, *args, **kwargs)
  File "C:\Users\Leo Huang\AppData\Local\Programs\Python\Python37\lib\site-packages\wandb\vendor\gql-0.2.0\gql\client.py", line 60, in _get_result
    return self.transport.execute(document, *args, **kwargs)
  File "C:\Users\Leo Huang\AppData\Local\Programs\Python\Python37\lib\site-packages\wandb\vendor\gql-0.2.0\gql\transport\requests.py", line 39, in execute
    request.raise_for_status()
  File "C:\Users\Leo Huang\AppData\Local\Programs\Python\Python37\lib\site-packages\requests\models.py", line 909, in raise_for_status
    raise HTTPError(http_error_msg, response=self)
requests.exceptions.HTTPError: 404 Client Error: Not Found for url: https://api.wandb.ai/graphql

During handling of the above exception, another exception occurred:

Traceback (most recent call last):
  File "C:\Users\Leo Huang\AppData\Local\Programs\Python\Python37\lib\site-packages\wandb\apis\normalize.py", line 24, in wrapper
    return func(*args, **kwargs)
  File "C:\Users\Leo Huang\AppData\Local\Programs\Python\Python37\lib\site-packages\wandb\sdk\internal\internal_api.py", line 883, in upsert_run
    response = self.gql(mutation, variable_values=variable_values, **kwargs)
  File "C:\Users\Leo Huang\AppData\Local\Programs\Python\Python37\lib\site-packages\wandb\old\retry.py", line 105, in __call__
    if not check_retry_fn(e):
  File "C:\Users\Leo Huang\AppData\Local\Programs\Python\Python37\lib\site-packages\wandb\util.py", line 713, in no_retry_auth
    raise CommError("Permission denied, ask the project owner to grant you access")
wandb.errors.CommError: Permission denied, ask the project owner to grant you access

During handling of the above exception, another exception occurred:

Traceback (most recent call last):
  File "C:\Users\Leo Huang\AppData\Local\Programs\Python\Python37\lib\site-packages\wandb\sdk\internal\internal_util.py", line 54, in run
    self._run()
  File "C:\Users\Leo Huang\AppData\Local\Programs\Python\Python37\lib\site-packages\wandb\sdk\internal\internal_util.py", line 95, in _run
    self._process(record)
  File "C:\Users\Leo Huang\AppData\Local\Programs\Python\Python37\lib\site-packages\wandb\sdk\internal\internal.py", line 279, in _process
    self._sm.send(record)
  File "C:\Users\Leo Huang\AppData\Local\Programs\Python\Python37\lib\site-packages\wandb\sdk\internal\sender.py", line 162, in send
    send_handler(record)
  File "C:\Users\Leo Huang\AppData\Local\Programs\Python\Python37\lib\site-packages\wandb\sdk\internal\sender.py", line 541, in send_run
    self._init_run(run, config_value_dict)
  File "C:\Users\Leo Huang\AppData\Local\Programs\Python\Python37\lib\site-packages\wandb\sdk\internal\sender.py", line 577, in _init_run
    commit=repo.last_commit,
  File "C:\Users\Leo Huang\AppData\Local\Programs\Python\Python37\lib\site-packages\wandb\apis\normalize.py", line 62, in wrapper
    six.reraise(CommError, CommError(message, err), sys.exc_info()[2])
  File "C:\Users\Leo Huang\AppData\Local\Programs\Python\Python37\lib\site-packages\six.py", line 702, in reraise
    raise value.with_traceback(tb)
  File "C:\Users\Leo Huang\AppData\Local\Programs\Python\Python37\lib\site-packages\wandb\apis\normalize.py", line 24, in wrapper
    return func(*args, **kwargs)
  File "C:\Users\Leo Huang\AppData\Local\Programs\Python\Python37\lib\site-packages\wandb\sdk\internal\internal_api.py", line 883, in upsert_run
    response = self.gql(mutation, variable_values=variable_values, **kwargs)
  File "C:\Users\Leo Huang\AppData\Local\Programs\Python\Python37\lib\site-packages\wandb\old\retry.py", line 105, in __call__
    if not check_retry_fn(e):
  File "C:\Users\Leo Huang\AppData\Local\Programs\Python\Python37\lib\site-packages\wandb\util.py", line 713, in no_retry_auth
    raise CommError("Permission denied, ask the project owner to grant you access")
wandb.errors.CommError: Permission denied, ask the project owner to grant you access
2021-04-09 15:02:01,066 INFO    MainThread:6392 [internal.py:handle_exit():78] Internal process exited
